Workbook
Name LEFTVARBLUE: Histogram!$B$4
Name rightVARBlue: Histogram!$B$6

Sheet INDEX
A4: WORKSHEET | H4: DESCRIPTION
A6: SUMMARY | H6: EVERYTHING IMPORTANT AT A GLANCE
A7: HISTORICAL RISK | H7: DETAILED HISTORICAL STATISTICS
A8: SIMULATED RISK | H8: DETAILED SIMULATED STATISTICS
A9: RISK BUDGETING (ETL) | H9: RISK BUDGETING ANALYSIS, BASED ON TAIL RISK
A10: RISK BUDGETING (StDev) | H10: RISK BUDGETING ANALYSIS, BASED ON TRADITIONAL RISK
A11: FACTOR CONTRIBUTION | H11: FACTOR CONTRIBUTION TO RISK; SYSTEMATIC VS. SPECIFIC FACTOR RISK
A12: EXPOSURE BY FACTOR BUCKET | H12: DETAILED EXPOSURES FROM FACTOR BUCKETS
A13: PORTFOLIO STRESS TEST | H13: SELECTED MULTI-FACTOR SCENARIO STRESS ANALYSIS
A14: STRESSED FACTOR VALUES | H14: FACTOR RETURNS UNDER THE SCENARIO STRESS ANALYSIS
A15: FACTOR ANALYSIS | H15: DETAILED RISK DRIVER ANALYSIS
A16: ASSET CORRELATIONS | H16: ASSET CLASSICAL VS ROBUST CORRELATIONS
... A19: GLOSSARY | H19: GLOSSARY OF THE USED STATISTICS
A24: CALCULATION SETTINGS | U24: Portfolio Composition
A25: PORTFOLIO | H25: ='SIMULATED RISK'!A9 -> Current 7.26
A26: PORTFOLIO VALUE | H26: 1000000
A27: NUMBER OF ASSETS | H27: 37
A28: BACKFILL | H28: No
A29: FACTOR MODEL | H29: Template General Factor Model
A30: DISTRIBUTION TYPE | H30: Asymmetric Student-t
A31: CORRELATIONS | H31: EWMA
A32: STRESS TESTS | H32: 11
A33: ANALYSIS PERIOD | H33: 07/31/2019 - 04/30/2026
A34: TIME WINDOW | H34: 81
A35: CONFIDENCE LEVEL | H35: 95
A36: RFR (Annualized) | H36: 4
A37: CURRENCY | H37: USD

Sheet Histogram
B1: HISTOGRAM (BLUE bars) | P1: RETURNS | R1: X-AXIS | T1: #SIMULATIONS per BIN | V1: #TAIL SIMULATIONS per BIN | X1: Tooltips BLUE | AB1: #TAIL SIMULATIONS per BIN
A2: Present Value (as of Evaluation Date) | B2: =INDEX!H26 -> 1000000 | P2: BLUE | T2: BLUE | V2: BLUE | X2: =UPPER($B$10 & CHAR(10) & TEXT($B$4,"0.00%")) -> VAR AT 95%, -0.29% | Y2: =UPPER($B$12 & CHAR(10) & TEXT($B$6,"0.00%")) -> VAR AT 5%, 2.06% | Z2: =UPPER($B$14 & CHAR(10) & TEXT($B$8,"0.00%")) -> MEAN, 0.94%
R3: -0.038627503 | T3: 0 | V3: =IF(OR(R3<LEFTVARBLUE,R3>rightVARBlue),IF(OR(AND(R4>=LEFTVARBLUE,R3<LEFTVARBLUE),AND(R3>=rightVARBlue,R2<rightVARBlue)),T3,T3),0) -> 0 | X3: =IF(AND(R4>=$B$4,R3<$B$4),MAX($T$3:$T$103)*1.1,NA()) -> #N/A | Y3: =IF(AND(R3>=$B$6,R2<$B$6),MAX($T$3:$T$103)*1.1,NA()) -> #N/A | Z3: =IF(AND(R3>=$B$8,R2<$B$8),MAX($T$3:$T$103)*1.1,NA()) -> #N/A | AB3: =IF(R3<LEFTVARBLUE,LEFTVARBLUE,0) -> -0.0028728808
A4: Left -tail VAR (as negative percentage) | B4: =SUMMARY!AD9/100 -> -0.0028728808 | R4: -0.037691282 | T4: 12 | V4: =IF(OR(R4<LEFTVARBLUE,R4>rightVARBlue),IF(OR(AND(R5>=LEFTVARBLUE,R4<LEFTVARBLUE),AND(R4>=rightVARBlue,R3<rightVARBlue)),T4,T4),0) -> 12 | X4: =IF(AND(R5>=$B$4,R4<$B$4),MAX($T$3:$T$103)*1.1,NA()) -> #N/A | Y4: =IF(AND(R4>=$B$6,R3<$B$6),MAX($T$3:$T$103)*1.1,NA()) -> #N/A | Z4: =IF(AND(R4>=$B$8,R3<$B$8),MAX($T$3:$T$103)*1.1,NA()) -> #N/A | AB4: =IF(R4<LEFTVARBLUE,LEFTVARBLUE,0) -> -0.0028728808
R5: -0.036755062 | T5: 6 | V5: =IF(OR(R5<LEFTVARBLUE,R5>rightVARBlue),IF(OR(AND(R6>=LEFTVARBLUE,R5<LEFTVARBLUE),AND(R5>=rightVARBlue,R4<rightVARBlue)),T5,T5),0) -> 6 | X5: =IF(AND(R6>=$B$4,R5<$B$4),MAX($T$3:$T$103)*1.1,NA()) -> #N/A | Y5: =IF(AND(R5>=$B$6,R4<$B$6),MAX($T$3:$T$103)*1.1,NA()) -> #N/A | Z5: =IF(AND(R5>=$B$8,R4<$B$8),MAX($T$3:$T$103)*1.1,NA()) -> #N/A | AB5: =IF(R5<LEFTVARBLUE,LEFTVARBLUE,0) -> -0.0028728808
A6: Right -tail VAR (as positive percentage) | B6: =SUMMARY!AF9/100 -> 0.020635408 | R6: -0.035818842 | T6: 6 | V6: =IF(OR(R6<LEFTVARBLUE,R6>rightVARBlue),IF(OR(AND(R7>=LEFTVARBLUE,R6<LEFTVARBLUE),AND(R6>=rightVARBlue,R5<rightVARBlue)),T6,T6),0) -> 6 | X6: =IF(AND(R7>=$B$4,R6<$B$4),MAX($T$3:$T$103)*1.1,NA()) -> #N/A | Y6: =IF(AND(R6>=$B$6,R5<$B$6),MAX($T$3:$T$103)*1.1,NA()) -> #N/A | Z6: =IF(AND(R6>=$B$8,R5<$B$8),MAX($T$3:$T$103)*1.1,NA()) -> #N/A | AB6: =IF(R6<LEFTVARBLUE,LEFTVARBLUE,0) -> -0.0028728808
R7: -0.034882621 | T7: 7 | V7: =IF(OR(R7<LEFTVARBLUE,R7>rightVARBlue),IF(OR(AND(R8>=LEFTVARBLUE,R7<LEFTVARBLUE),AND(R7>=rightVARBlue,R6<rightVARBlue)),T7,T7),0) -> 7 | X7: =IF(AND(R8>=$B$4,R7<$B$4),MAX($T$3:$T$103)*1.1,NA()) -> #N/A | Y7: =IF(AND(R7>=$B$6,R6<$B$6),MAX($T$3:$T$103)*1.1,NA()) -> #N/A | Z7: =IF(AND(R7>=$B$8,R6<$B$8),MAX($T$3:$T$103)*1.1,NA()) -> #N/A | AB7: =IF(R7<LEFTVARBLUE,LEFTVARBLUE,0) -> -0.0028728808
A8: Mean (as positive percentage) | B8: =SUMMARY!W9/100 -> 0.009376494 | R8: -0.033946401 | T8: 10 | V8: =IF(OR(R8<LEFTVARBLUE,R8>rightVARBlue),IF(OR(AND(R9>=LEFTVARBLUE,R8<LEFTVARBLUE),AND(R8>=rightVARBlue,R7<rightVARBlue)),T8,T8),0) -> 10 | X8: =IF(AND(R9>=$B$4,R8<$B$4),MAX($T$3:$T$103)*1.1,NA()) -> #N/A | Y8: =IF(AND(R8>=$B$6,R7<$B$6),MAX($T$3:$T$103)*1.1,NA()) -> #N/A | Z8: =IF(AND(R8>=$B$8,R7<$B$8),MAX($T$3:$T$103)*1.1,NA()) -> #N/A | AB8: =IF(R8<LEFTVARBLUE,LEFTVARBLUE,0) -> -0.0028728808
R9: -0.03301018 | T9: 16 | V9: =IF(OR(R9<LEFTVARBLUE,R9>rightVARBlue),IF(OR(AND(R10>=LEFTVARBLUE,R9<LEFTVARBLUE),AND(R9>=rightVARBlue,R8<rightVARBlue)),T9,T9),0) -> 16 | X9: =IF(AND(R10>=$B$4,R9<$B$4),MAX($T$3:$T$103)*1.1,NA()) -> #N/A | Y9: =IF(AND(R9>=$B$6,R8<$B$6),MAX($T$3:$T$103)*1.1,NA()) -> #N/A | Z9: =IF(AND(R9>=$B$8,R8<$B$8),MAX($T$3:$T$103)*1.1,NA()) -> #N/A | AB9: =IF(R9<LEFTVARBLUE,LEFTVARBLUE,0) -> -0.0028728808
A10: Tooltip Name for left-tail VAR | B10: VAR at 95%, | R10: -0.03207396 | T10: 15 | V10: =IF(OR(R10<LEFTVARBLUE,R10>rightVARBlue),IF(OR(AND(R11>=LEFTVARBLUE,R10<LEFTVARBLUE),AND(R10>=rightVARBlue,R9<rightVARBlue)),T10,T10),0) -> 15 | X10: =IF(AND(R11>=$B$4,R10<$B$4),MAX($T$3:$T$103)*1.1,NA()) -> #N/A | Y10: =IF(AND(R10>=$B$6,R9<$B$6),MAX($T$3:$T$103)*1.1,NA()) -> #N/A | Z10: =IF(AND(R10>=$B$8,R9<$B$8),MAX($T$3:$T$103)*1.1,NA()) -> #N/A | AB10: =IF(R10<LEFTVARBLUE,LEFTVARBLUE,0) -> -0.0028728808
R11: -0.03113774 | T11: 17 | V11: =IF(OR(R11<LEFTVARBLUE,R11>rightVARBlue),IF(OR(AND(R12>=LEFTVARBLUE,R11<LEFTVARBLUE),AND(R11>=rightVARBlue,R10<rightVARBlue)),T11,T11),0) -> 17 | X11: =IF(AND(R12>=$B$4,R11<$B$4),MAX($T$3:$T$103)*1.1,NA()) -> #N/A | Y11: =IF(AND(R11>=$B$6,R10<$B$6),MAX($T$3:$T$103)*1.1,NA()) -> #N/A | Z11: =IF(AND(R11>=$B$8,R10<$B$8),MAX($T$3:$T$103)*1.1,NA()) -> #N/A | AB11: =IF(R11<LEFTVARBLUE,LEFTVARBLUE,0) -> -0.0028728808
A12: Tooltip Name for right-tail VAR | B12: VAR at 5%, | R12: -0.030201519 | T12: 20 | V12: =IF(OR(R12<LEFTVARBLUE,R12>rightVARBlue),IF(OR(AND(R13>=LEFTVARBLUE,R12<LEFTVARBLUE),AND(R12>=rightVARBlue,R11<rightVARBlue)),T12,T12),0) -> 20 | X12: =IF(AND(R13>=$B$4,R12<$B$4),MAX($T$3:$T$103)*1.1,NA()) -> #N/A | Y12: =IF(AND(R12>=$B$6,R11<$B$6),MAX($T$3:$T$103)*1.1,NA()) -> #N/A | Z12: =IF(AND(R12>=$B$8,R11<$B$8),MAX($T$3:$T$103)*1.1,NA()) -> #N/A | AB12: =IF(R12<LEFTVARBLUE,LEFTVARBLUE,0) -> -0.0028728808
R13: -0.029265299 | T13: 25 | V13: =IF(OR(R13<LEFTVARBLUE,R13>rightVARBlue),IF(OR(AND(R14>=LEFTVARBLUE,R13<LEFTVARBLUE),AND(R13>=rightVARBlue,R12<rightVARBlue)),T13,T13),0) -> 25 | X13: =IF(AND(R14>=$B$4,R13<$B$4),MAX($T$3:$T$103)*1.1,NA()) -> #N/A | Y13: =IF(AND(R13>=$B$6,R12<$B$6),MAX($T$3:$T$103)*1.1,NA()) -> #N/A | Z13: =IF(AND(R13>=$B$8,R12<$B$8),MAX($T$3:$T$103)*1.1,NA()) -> #N/A | AB13: =IF(R13<LEFTVARBLUE,LEFTVARBLUE,0) -> -0.0028728808
A14: Tooltip Name for right-tail VAR | B14: Mean, | R14: -0.028329078 | T14: 21 | V14: =IF(OR(R14<LEFTVARBLUE,R14>rightVARBlue),IF(OR(AND(R15>=LEFTVARBLUE,R14<LEFTVARBLUE),AND(R14>=rightVARBlue,R13<rightVARBlue)),T14,T14),0) -> 21 | X14: =IF(AND(R15>=$B$4,R14<$B$4),MAX($T$3:$T$103)*1.1,NA()) -> #N/A | Y14: =IF(AND(R14>=$B$6,R13<$B$6),MAX($T$3:$T$103)*1.1,NA()) -> #N/A | Z14: =IF(AND(R14>=$B$8,R13<$B$8),MAX($T$3:$T$103)*1.1,NA()) -> #N/A | AB14: =IF(R14<LEFTVARBLUE,LEFTVARBLUE,0) -> -0.0028728808
R15: -0.027392858 | T15: 18 | V15: =IF(OR(R15<LEFTVARBLUE,R15>rightVARBlue),IF(OR(AND(R16>=LEFTVARBLUE,R15<LEFTVARBLUE),AND(R15>=rightVARBlue,R14<rightVARBlue)),T15,T15),0) -> 18 | X15: =IF(AND(R16>=$B$4,R15<$B$4),MAX($T$3:$T$103)*1.1,NA()) -> #N/A | Y15: =IF(AND(R15>=$B$6,R14<$B$6),MAX($T$3:$T$103)*1.1,NA()) -> #N/A | Z15: =IF(AND(R15>=$B$8,R14<$B$8),MAX($T$3:$T$103)*1.1,NA()) -> #N/A | AB15: =IF(R15<LEFTVARBLUE,LEFTVARBLUE,0) -> -0.0028728808
R16: -0.026456638 | T16: 22 | V16: =IF(OR(R16<LEFTVARBLUE,R16>rightVARBlue),IF(OR(AND(R17>=LEFTVARBLUE,R16<LEFTVARBLUE),AND(R16>=rightVARBlue,R15<rightVARBlue)),T16,T16),0) -> 22 | X16: =IF(AND(R17>=$B$4,R16<$B$4),MAX($T$3:$T$103)*1.1,NA()) -> #N/A | Y16: =IF(AND(R16>=$B$6,R15<$B$6),MAX($T$3:$T$103)*1.1,NA()) -> #N/A | Z16: =IF(AND(R16>=$B$8,R15<$B$8),MAX($T$3:$T$103)*1.1,NA()) -> #N/A | AB16: =IF(R16<LEFTVARBLUE,LEFTVARBLUE,0) -> -0.0028728808
A17: Simulations | R17: -0.025520417 | T17: 28 | V17: =IF(OR(R17<LEFTVARBLUE,R17>rightVARBlue),IF(OR(AND(R18>=LEFTVARBLUE,R17<LEFTVARBLUE),AND(R17>=rightVARBlue,R16<rightVARBlue)),T17,T17),0) -> 28 | X17: =IF(AND(R18>=$B$4,R17<$B$4),MAX($T$3:$T$103)*1.1,NA()) -> #N/A | Y17: =IF(AND(R17>=$B$6,R16<$B$6),MAX($T$3:$T$103)*1.1,NA()) -> #N/A | Z17: =IF(AND(R17>=$B$8,R16<$B$8),MAX($T$3:$T$103)*1.1,NA()) -> #N/A | AB17: =IF(R17<LEFTVARBLUE,LEFTVARBLUE,0) -> -0.0028728808
R18: -0.024584197 | T18: 31 | V18: =IF(OR(R18<LEFTVARBLUE,R18>rightVARBlue),IF(OR(AND(R19>=LEFTVARBLUE,R18<LEFTVARBLUE),AND(R18>=rightVARBlue,R17<rightVARBlue)),T18,T18),0) -> 31 | X18: =IF(AND(R19>=$B$4,R18<$B$4),MAX($T$3:$T$103)*1.1,NA()) -> #N/A | Y18: =IF(AND(R18>=$B$6,R17<$B$6),MAX($T$3:$T$103)*1.1,NA()) -> #N/A | Z18: =IF(AND(R18>=$B$8,R17<$B$8),MAX($T$3:$T$103)*1.1,NA()) -> #N/A | AB18: =IF(R18<LEFTVARBLUE,LEFTVARBLUE,0) -> -0.0028728808
R19: -0.023647977 | T19: 22 | V19: =IF(OR(R19<LEFTVARBLUE,R19>rightVARBlue),IF(OR(AND(R20>=LEFTVARBLUE,R19<LEFTVARBLUE),AND(R19>=rightVARBlue,R18<rightVARBlue)),T19,T19),0) -> 22 | X19: =IF(AND(R20>=$B$4,R19<$B$4),MAX($T$3:$T$103)*1.1,NA()) -> #N/A | Y19: =IF(AND(R19>=$B$6,R18<$B$6),MAX($T$3:$T$103)*1.1,NA()) -> #N/A | Z19: =IF(AND(R19>=$B$8,R18<$B$8),MAX($T$3:$T$103)*1.1,NA()) -> #N/A | AB19: =IF(R19<LEFTVARBLUE,LEFTVARBLUE,0) -> -0.0028728808
R20: -0.022711756 | T20: 44 | V20: =IF(OR(R20<LEFTVARBLUE,R20>rightVARBlue),IF(OR(AND(R21>=LEFTVARBLUE,R20<LEFTVARBLUE),AND(R20>=rightVARBlue,R19<rightVARBlue)),T20,T20),0) -> 44 | X20: =IF(AND(R21>=$B$4,R20<$B$4),MAX($T$3:$T$103)*1.1,NA()) -> #N/A | Y20: =IF(AND(R20>=$B$6,R19<$B$6),MAX($T$3:$T$103)*1.1,NA()) -> #N/A | Z20: =IF(AND(R20>=$B$8,R19<$B$8),MAX($T$3:$T$103)*1.1,NA()) -> #N/A | AB20: =IF(R20<LEFTVARBLUE,LEFTVARBLUE,0) -> -0.0028728808
R21: -0.021775536 | T21: 45 | V21: =IF(OR(R21<LEFTVARBLUE,R21>rightVARBlue),IF(OR(AND(R22>=LEFTVARBLUE,R21<LEFTVARBLUE),AND(R21>=rightVARBlue,R20<rightVARBlue)),T21,T21),0) -> 45 | X21: =IF(AND(R22>=$B$4,R21<$B$4),MAX($T$3:$T$103)*1.1,NA()) -> #N/A | Y21: =IF(AND(R21>=$B$6,R20<$B$6),MAX($T$3:$T$103)*1.1,NA()) -> #N/A | Z21: =IF(AND(R21>=$B$8,R20<$B$8),MAX($T$3:$T$103)*1.1,NA()) -> #N/A | AB21: =IF(R21<LEFTVARBLUE,LEFTVARBLUE,0) -> -0.0028728808
R22: -0.020839315 | T22: 45 | V22: =IF(OR(R22<LEFTVARBLUE,R22>rightVARBlue),IF(OR(AND(R23>=LEFTVARBLUE,R22<LEFTVARBLUE),AND(R22>=rightVARBlue,R21<rightVARBlue)),T22,T22),0) -> 45 | X22: =IF(AND(R23>=$B$4,R22<$B$4),MAX($T$3:$T$103)*1.1,NA()) -> #N/A | Y22: =IF(AND(R22>=$B$6,R21<$B$6),MAX($T$3:$T$103)*1.1,NA()) -> #N/A | Z22: =IF(AND(R22>=$B$8,R21<$B$8),MAX($T$3:$T$103)*1.1,NA()) -> #N/A | AB22: =IF(R22<LEFTVARBLUE,LEFTVARBLUE,0) -> -0.0028728808
R23: -0.019903095 | T23: 60 | V23: =IF(OR(R23<LEFTVARBLUE,R23>rightVARBlue),IF(OR(AND(R24>=LEFTVARBLUE,R23<LEFTVARBLUE),AND(R23>=rightVARBlue,R22<rightVARBlue)),T23,T23),0) -> 60 | X23: =IF(AND(R24>=$B$4,R23<$B$4),MAX($T$3:$T$103)*1.1,NA()) -> #N/A | Y23: =IF(AND(R23>=$B$6,R22<$B$6),MAX($T$3:$T$103)*1.1,NA()) -> #N/A | Z23: =IF(AND(R23>=$B$8,R22<$B$8),MAX($T$3:$T$103)*1.1,NA()) -> #N/A | AB23: =IF(R23<LEFTVARBLUE,LEFTVARBLUE,0) -> -0.0028728808
R24: -0.018966875 | T24: 62 | V24: =IF(OR(R24<LEFTVARBLUE,R24>rightVARBlue),IF(OR(AND(R25>=LEFTVARBLUE,R24<LEFTVARBLUE),AND(R24>=rightVARBlue,R23<rightVARBlue)),T24,T24),0) -> 62 | X24: =IF(AND(R25>=$B$4,R24<$B$4),MAX($T$3:$T$103)*1.1,NA()) -> #N/A | Y24: =IF(AND(R24>=$B$6,R23<$B$6),MAX($T$3:$T$103)*1.1,NA()) -> #N/A | Z24: =IF(AND(R24>=$B$8,R23<$B$8),MAX($T$3:$T$103)*1.1,NA()) -> #N/A | AB24: =IF(R24<LEFTVARBLUE,LEFTVARBLUE,0) -> -0.0028728808
R25: -0.018030654 | T25: 70 | V25: =IF(OR(R25<LEFTVARBLUE,R25>rightVARBlue),IF(OR(AND(R26>=LEFTVARBLUE,R25<LEFTVARBLUE),AND(R25>=rightVARBlue,R24<rightVARBlue)),T25,T25),0) -> 70 | X25: =IF(AND(R26>=$B$4,R25<$B$4),MAX($T$3:$T$103)*1.1,NA()) -> #N/A | Y25: =IF(AND(R25>=$B$6,R24<$B$6),MAX($T$3:$T$103)*1.1,NA()) -> #N/A | Z25: =IF(AND(R25>=$B$8,R24<$B$8),MAX($T$3:$T$103)*1.1,NA()) -> #N/A | AB25: =IF(R25<LEFTVARBLUE,LEFTVARBLUE,0) -> -0.0028728808
R26: -0.017094434 | T26: 67 | V26: =IF(OR(R26<LEFTVARBLUE,R26>rightVARBlue),IF(OR(AND(R27>=LEFTVARBLUE,R26<LEFTVARBLUE),AND(R26>=rightVARBlue,R25<rightVARBlue)),T26,T26),0) -> 67 | X26: =IF(AND(R27>=$B$4,R26<$B$4),MAX($T$3:$T$103)*1.1,NA()) -> #N/A | Y26: =IF(AND(R26>=$B$6,R25<$B$6),MAX($T$3:$T$103)*1.1,NA()) -> #N/A | Z26: =IF(AND(R26>=$B$8,R25<$B$8),MAX($T$3:$T$103)*1.1,NA()) -> #N/A | AB26: =IF(R26<LEFTVARBLUE,LEFTVARBLUE,0) -> -0.0028728808
R27: -0.016158214 | T27: 103 | V27: =IF(OR(R27<LEFTVARBLUE,R27>rightVARBlue),IF(OR(AND(R28>=LEFTVARBLUE,R27<LEFTVARBLUE),AND(R27>=rightVARBlue,R26<rightVARBlue)),T27,T27),0) -> 103 | X27: =IF(AND(R28>=$B$4,R27<$B$4),MAX($T$3:$T$103)*1.1,NA()) -> #N/A | Y27: =IF(AND(R27>=$B$6,R26<$B$6),MAX($T$3:$T$103)*1.1,NA()) -> #N/A | Z27: =IF(AND(R27>=$B$8,R26<$B$8),MAX($T$3:$T$103)*1.1,NA()) -> #N/A | AB27: =IF(R27<LEFTVARBLUE,LEFTVARBLUE,0) -> -0.0028728808
R28: -0.015221993 | T28: 96 | V28: =IF(OR(R28<LEFTVARBLUE,R28>rightVARBlue),IF(OR(AND(R29>=LEFTVARBLUE,R28<LEFTVARBLUE),AND(R28>=rightVARBlue,R27<rightVARBlue)),T28,T28),0) -> 96 | X28: =IF(AND(R29>=$B$4,R28<$B$4),MAX($T$3:$T$103)*1.1,NA()) -> #N/A | Y28: =IF(AND(R28>=$B$6,R27<$B$6),MAX($T$3:$T$103)*1.1,NA()) -> #N/A | Z28: =IF(AND(R28>=$B$8,R27<$B$8),MAX($T$3:$T$103)*1.1,NA()) -> #N/A | AB28: =IF(R28<LEFTVARBLUE,LEFTVARBLUE,0) -> -0.0028728808
R29: -0.014285773 | T29: 141 | V29: =IF(OR(R29<LEFTVARBLUE,R29>rightVARBlue),IF(OR(AND(R30>=LEFTVARBLUE,R29<LEFTVARBLUE),AND(R29>=rightVARBlue,R28<rightVARBlue)),T29,T29),0) -> 141 | X29: =IF(AND(R30>=$B$4,R29<$B$4),MAX($T$3:$T$103)*1.1,NA()) -> #N/A | Y29: =IF(AND(R29>=$B$6,R28<$B$6),MAX($T$3:$T$103)*1.1,NA()) -> #N/A | Z29: =IF(AND(R29>=$B$8,R28<$B$8),MAX($T$3:$T$103)*1.1,NA()) -> #N/A | AB29: =IF(R29<LEFTVARBLUE,LEFTVARBLUE,0) -> -0.0028728808
... R103: 0.054994535 | T103: 1 | V103: =IF(OR(R103<LEFTVARBLUE,R103>rightVARBlue),IF(OR(AND(R104>=LEFTVARBLUE,R103<LEFTVARBLUE),AND(R103>=rightVARBlue,R102<rightVARBlue)),T103,T103),0) -> 1 | X103: =IF(AND(R104>=$B$4,R103<$B$4),MAX($T$3:$T$103)*1.1,NA()) -> #N/A | Y103: =IF(AND(R103>=$B$6,R102<$B$6),MAX($T$3:$T$103)*1.1,NA()) -> #N/A | Z103: =IF(AND(R103>=$B$8,R102<$B$8),MAX($T$3:$T$103)*1.1,NA()) -> #N/A | AB103: =IF(R103<LEFTVARBLUE,LEFTVARBLUE,0) -> 0

Sheet SUMMARY
A4: PORTFOLIO RISK SNAPSHOT
A6: SIMULATIONS DISTRIBUTION CHART | S6: SIMULATED PORTFOLIO RISK STATISTICS
S7: TRADITIONAL | AB7: TAIL MEASURES
S8: StDev | U8: Ann. StDev | W8: Mean | Y8: Ann. Mean | AB8: ETL 95 | AD8: VaR 95 | AF8: VaR 5 | AH8: ETR 95
S9: =IF(ISBLANK(SUMMARY_DATA!B16)=TRUE,"",SUMMARY_DATA!B16) -> 0.75095534 | U9: =IF(ISBLANK(SUMMARY_DATA!C16)=TRUE,"",SUMMARY_DATA!C16) -> 2.6013856 | W9: =IF(ISBLANK(SUMMARY_DATA!D16)=TRUE,"",SUMMARY_DATA!D16) -> 0.9376494 | Y9: =IF(ISBLANK(SUMMARY_DATA!E16)=TRUE,"",SUMMARY_DATA!E16) -> 11.251793 | AB9: =IF(ISBLANK(SUMMARY_DATA!F16)=TRUE,"",SUMMARY_DATA!F16) -> 0.87394068 | AD9: =IF(ISBLANK(SUMMARY_DATA!G16)=TRUE,"",SUMMARY_DATA!G16*(-1)) -> -0.28728808 | AF9: =IF(ISBLANK(SUMMARY_DATA!H16)=TRUE,"",SUMMARY_DATA!H16*(-1)) -> 2.0635408 | AH9: =IF(ISBLANK(SUMMARY_DATA!I16)=TRUE,"",SUMMARY_DATA!I16) -> 2.4409617
S11: TOP 10 FACTORS BY SYSTEMATIC RISK (STDEV) | AB11: TOP 10 FACTORS BY SYSTEMATIC RISK (ETL)
W12: Factor PC to StDev | Y12: Factor MC to StDev | AF12: Factor PC to ETL | AH12: Factor MC to ETL
S13: TOTAL SYSTEMATIC RISK | W13: =SUMMARY_DATA!B23 -> 47.149713 | AB13: TOTAL SYSTEMATIC RISK | AF13: =SUMMARY_DATA!B26 -> 115.77315
S14: ML Global High Yield - AAA Spread USD | W14: 40.774773 | Y14: 1.5212307 | AB14: ML Global High Yield - AAA Spread USD | AF14: 101.54616 | AH14: 4.408947
S15: MSCI Small Minus Large World USD | W15: 4.6628847 | Y15: 0.92771053 | AB15: MSCI Small Minus Large World USD | AF15: 12.4419 | AH15: 2.8807951
S16: MSCI The World USD | W16: 3.2915027 | Y16: 1.6779847 | AB16: MSCI The World USD | AF16: 6.8117282 | AH16: 4.0412801
S17: ML Global Govt Bond II USD | W17: 1.9769688 | Y17: -0.3459997 | AB17: ML Global Govt Bond II USD | AF17: 2.3484622 | AH17: -0.47832969
S18: CBOE Volatility Index as Difference USD | W18: 0.80402133 | Y18: -1.244496 | AB18: CBOE Volatility Index as Difference USD | AF18: 1.6721821 | AH18: -3.0121552
S19: US Treasury 10Yr - 2Yr Spread USD | W19: 0.061423329 | Y19: 0.64135966 | AB19: US Treasury 10Yr - 2Yr Spread USD | AF19: 0.12630521 | AH19: 1.5348198
S20: MSCI Value Minus Growth World USD | W20: -0.18859047 | Y20: 0.10299873 | AB20: MSCI Value Minus Growth World USD | AF20: -0.17970689 | AH20: 0.11422066
S21: Trade Weighted Exchange Index: Broad | W21: -0.20667012 | Y21: -0.35462328 | AB21: Trade Weighted Exchange Index: Broad | AF21: -0.5659147 | AH21: -1.1300779
S22: S&P GSCI Index | W22: -4.0265997 | Y22: 2.5408459 | AB22: S&P GSCI Index | AF22: -8.4279646 | AH22: 6.1891416
S24: SPECIFIC RISK | W24: =100-W13 -> 52.850287 | AB24: SPECIFIC RISK | AF24: =100-AF13 -> -15.773153
A27: STRESS TEST SNAPSHOT
A29: TOP LOSER BY STRESS SCENARIO | I29: SCENARIOS BY PORTFOLIO IMPACT
F30: Asset Return | O30: Portfolio Return
A31: =IF(F31="","",INDEX(SCENARIOS_ORDERED_BY_PF_VALUE!A:A,MATCH(F31,SCENARIOS_ORDERED_BY_PF_VALUE!D:D,0))) -> Silver Point Capital: Silver Point Distressed Opportunity Institutional Partners + Silver Point HF | F31: =IF(ISBLANK(SCENARIOS_ORDERED_BY_PF_VALUE!D1)=TRUE,"",MIN(SCENARIOS_ORDERED_BY_PF_VALUE!D2:'SCENARIOS_ORDERED_BY_PF_VALUE'!D100)) -> -42.289325 | I31: =IF('PORTFOLIO STRESS TEST'!O13="%scenario", "", 'PORTFOLIO STRESS TEST'!O13) -> 2008 Lehman Blow-Up | O31: =IF('PORTFOLIO STRESS TEST'!O13="%scenario", "", 'PORTFOLIO STRESS TEST'!O14) -> -3.5256818
A32: =IF(F32="","",INDEX(SCENARIOS_ORDERED_BY_PF_VALUE!A:A,MATCH(F32,SCENARIOS_ORDERED_BY_PF_VALUE!E:E,0))) -> PIMCO: PIMCO Commodity Alpha Fund | F32: =IF(ISBLANK(SCENARIOS_ORDERED_BY_PF_VALUE!E1)=TRUE,"",MIN(SCENARIOS_ORDERED_BY_PF_VALUE!E2:'SCENARIOS_ORDERED_BY_PF_VALUE'!E100)) -> -26.684504 | I32: =IF('PORTFOLIO STRESS TEST'!Q13="%scenario", "", 'PORTFOLIO STRESS TEST'!Q13) -> 2002 Market Downturn | O32: =IF('PORTFOLIO STRESS TEST'!Q13="%scenario", "", 'PORTFOLIO STRESS TEST'!Q14) -> -1.7508844
A33: =IF(F33="","",INDEX(SCENARIOS_ORDERED_BY_PF_VALUE!A:A,MATCH(F33,SCENARIOS_ORDERED_BY_PF_VALUE!F:F,0))) -> Silver Point Capital: Silver Point Distressed Opportunity Institutional Partners + Silver Point HF | F33: =IF(ISBLANK(SCENARIOS_ORDERED_BY_PF_VALUE!F1)=TRUE,"",MIN(SCENARIOS_ORDERED_BY_PF_VALUE!F2:'SCENARIOS_ORDERED_BY_PF_VALUE'!F100)) -> -11.380305 | I33: =IF('PORTFOLIO STRESS TEST'!S13="%scenario", "", 'PORTFOLIO STRESS TEST'!S13) -> 2001 WTC Attack | O33: =IF('PORTFOLIO STRESS TEST'!S13="%scenario", "", 'PORTFOLIO STRESS TEST'!S14) -> -1.1625695
A34: =IF(F34="","",INDEX(SCENARIOS_ORDERED_BY_PF_VALUE!A:A,MATCH(F34,SCENARIOS_ORDERED_BY_PF_VALUE!G:G,0))) -> Silver Point Capital: Silver Point Distressed Opportunity Institutional Partners + Silver Point HF | F34: =IF(ISBLANK(SCENARIOS_ORDERED_BY_PF_VALUE!G1)=TRUE,"",MIN(SCENARIOS_ORDERED_BY_PF_VALUE!G2:'SCENARIOS_ORDERED_BY_PF_VALUE'!G100)) -> -28.416508 | I34: =IF('PORTFOLIO STRESS TEST'!U13="%scenario", "", 'PORTFOLIO STRESS TEST'!U13) -> 1987 Black Monday | O34: =IF('PORTFOLIO STRESS TEST'!U13="%scenario", "", 'PORTFOLIO STRESS TEST'!U14) -> -0.6952119
A35: =IF(F35="","",INDEX(SCENARIOS_ORDERED_BY_PF_VALUE!A:A,MATCH(F35,SCENARIOS_ORDERED_BY_PF_VALUE!H:H,0))) -> PIMCO: PIMCO Commodity Alpha Fund | F35: =IF(ISBLANK(SCENARIOS_ORDERED_BY_PF_VALUE!H1)=TRUE,"",MIN(SCENARIOS_ORDERED_BY_PF_VALUE!H2:'SCENARIOS_ORDERED_BY_PF_VALUE'!H100)) -> -7.5970198 | I35: =IF('PORTFOLIO STRESS TEST'!W13="%scenario", "", 'PORTFOLIO STRESS TEST'!W13) -> 1998 Russian Crisis | O35: =IF('PORTFOLIO STRESS TEST'!W13="%scenario", "", 'PORTFOLIO STRESS TEST'!W14) -> -0.68043189
A36: =IF(F36="","",INDEX(SCENARIOS_ORDERED_BY_PF_VALUE!A:A,MATCH(F36,SCENARIOS_ORDERED_BY_PF_VALUE!I:I,0))) -> PIMCO: PIMCO Commodity Alpha Fund | F36: =IF(ISBLANK(SCENARIOS_ORDERED_BY_PF_VALUE!I1)=TRUE,"",MIN(SCENARIOS_ORDERED_BY_PF_VALUE!I2:'SCENARIOS_ORDERED_BY_PF_VALUE'!I100)) -> -7.5670559 | I36: =IF('PORTFOLIO STRESS TEST'!Y13="%scenario", "", 'PORTFOLIO STRESS TEST'!Y13) -> 2008 January Crisis | O36: =IF('PORTFOLIO STRESS TEST'!Y13="%scenario", "", 'PORTFOLIO STRESS TEST'!Y14) -> -0.30050481
A37: =IF(F37="","",INDEX(SCENARIOS_ORDERED_BY_PF_VALUE!A:A,MATCH(F37,SCENARIOS_ORDERED_BY_PF_VALUE!J:J,0))) -> Saba: CEF1 MN - 2.75x | F37: =IF(ISBLANK(SCENARIOS_ORDERED_BY_PF_VALUE!J1)=TRUE,"",MIN(SCENARIOS_ORDERED_BY_PF_VALUE!J2:'SCENARIOS_ORDERED_BY_PF_VALUE'!J100)) -> -3.8341475 | I37: =IF('PORTFOLIO STRESS TEST'!AA13="%scenario", "", 'PORTFOLIO STRESS TEST'!AA13) -> 2007 August Crisis | O37: =IF('PORTFOLIO STRESS TEST'!AA13="%scenario", "", 'PORTFOLIO STRESS TEST'!AA14) -> -0.024435815
A38: =IF(F38="","",INDEX(SCENARIOS_ORDERED_BY_PF_VALUE!A:A,MATCH(F38,SCENARIOS_ORDERED_BY_PF_VALUE!K:K,0))) -> Silver Point Capital: Silver Point Distressed Opportunity Institutional Partners + Silver Point HF | F38: =IF(ISBLANK(SCENARIOS_ORDERED_BY_PF_VALUE!K1)=TRUE,"",MIN(SCENARIOS_ORDERED_BY_PF_VALUE!K2:'SCENARIOS_ORDERED_BY_PF_VALUE'!K100)) -> -8.6402481 | I38: =IF('PORTFOLIO STRESS TEST'!AC13="%scenario", "", 'PORTFOLIO STRESS TEST'!AC13) -> 2001 Nasdaq | O38: =IF('PORTFOLIO STRESS TEST'!AC13="%scenario", "", 'PORTFOLIO STRESS TEST'!AC14) -> 0.072055902
A39: =IF(F39="","",INDEX(SCENARIOS_ORDERED_BY_PF_VALUE!A:A,MATCH(F39,SCENARIOS_ORDERED_BY_PF_VALUE!L:L,0))) -> PIMCO: PIMCO Commodity Alpha Fund | F39: =IF(ISBLANK(SCENARIOS_ORDERED_BY_PF_VALUE!L1)=TRUE,"",MIN(SCENARIOS_ORDERED_BY_PF_VALUE!L2:'SCENARIOS_ORDERED_BY_PF_VALUE'!L100)) -> -2.779568 | I39: =IF('PORTFOLIO STRESS TEST'!AE13="%scenario", "", 'PORTFOLIO STRESS TEST'!AE13) -> 1997 - 1998 Asian Crisis | O39: =IF('PORTFOLIO STRESS TEST'!AE13="%scenario", "", 'PORTFOLIO STRESS TEST'!AE14) -> 0.1020368
A40: =IF(F40="","",INDEX(SCENARIOS_ORDERED_BY_PF_VALUE!A:A,MATCH(F40,SCENARIOS_ORDERED_BY_PF_VALUE!M:M,0))) -> Rokos Global Macro Fund LP: Rokos Global Macro Fund LP | F40: =IF(ISBLANK(SCENARIOS_ORDERED_BY_PF_VALUE!M1)=TRUE,"",MIN(SCENARIOS_ORDERED_BY_PF_VALUE!M2:'SCENARIOS_ORDERED_BY_PF_VALUE'!M100)) -> -7.6864085 | I40: =IF('PORTFOLIO STRESS TEST'!AG13="%scenario", "", 'PORTFOLIO STRESS TEST'!AG13) -> 1990 Kuwait Invasion | O40: =IF('PORTFOLIO STRESS TEST'!AG13="%scenario", "", 'PORTFOLIO STRESS TEST'!AG14) -> 0.29266168
A41: =IF(F41="","",INDEX(SCENARIOS_ORDERED_BY_PF_VALUE!A:A,MATCH(F41,SCENARIOS_ORDERED_BY_PF_VALUE!N:N,0))) -> Silver Point Capital: Silver Point Distressed Opportunity Institutional Partners + Silver Point HF | F41: =IF(ISBLANK(SCENARIOS_ORDERED_BY_PF_VALUE!N1)=TRUE,"",MIN(SCENARIOS_ORDERED_BY_PF_VALUE!N2:'SCENARIOS_ORDERED_BY_PF_VALUE'!N100)) -> -2.802416 | I41: =IF('PORTFOLIO STRESS TEST'!AI13="%scenario", "", 'PORTFOLIO STRESS TEST'!AI13) -> 2005 Katrina | O41: =IF('PORTFOLIO STRESS TEST'!AI13="%scenario", "", 'PORTFOLIO STRESS TEST'!AI14) -> 1.1043836
A45: PORTFOLIO RISK CONTRIBUTION SNAPSHOT
A47: TOP 5 CONTRIBUTORS BY MARGINAL CONTRIBUTION TO ETL | N47: PERCENTAGE CONTRIBUTION (%) | AA47: MARGINAL CONTRIBUTION (bps)
J48: Weight | N48: PC to ETL • | P48: PC to ETR • | R48: PC to StDev | T48: PC to Return | AA48: MC to ETL • | AC48: MC to ETR • | AE48: MC to StDev
A49: =IF(ISBLANK(SUMMARY_DATA!A2)=TRUE,"",SUMMARY_DATA!A2) -> Silver Point Capital: Silver Point Distressed Opportunity Institutional Partners + Silver Point HF | J49: =IF(ISBLANK(SUMMARY_DATA!B2)=TRUE,"",SUMMARY_DATA!B2) -> 0.77463136 | N49: =IF(ISBLANK(SUMMARY_DATA!C2)=TRUE,"",SUMMARY_DATA!C2) -> 7.5420822 | P49: =IF(ISBLANK(SUMMARY_DATA!D2)=TRUE,"",SUMMARY_DATA!D2) -> 2.0514522 | R49: =IF(ISBLANK(SUMMARY_DATA!E2)=TRUE,"",SUMMARY_DATA!E2) -> 3.4079492 | T49: =IF(ISBLANK(SUMMARY_DATA!F2)=TRUE,"",SUMMARY_DATA!F2) -> 0.96608254 | AA49: =IF(ISBLANK(SUMMARY_DATA!G2)=TRUE,"",SUMMARY_DATA!G2) -> 8.5089926 | AC49: =IF(ISBLANK(SUMMARY_DATA!H2)=TRUE,"",SUMMARY_DATA!H2) -> 6.464386 | AE49: =IF(ISBLANK(SUMMARY_DATA!I2)=TRUE,"",SUMMARY_DATA!I2) -> 3.3037878
A50: =IF(ISBLANK(SUMMARY_DATA!A3)=TRUE,"",SUMMARY_DATA!A3) -> LibreMax Partners LP: LibreMax Partners LP | J50: =IF(ISBLANK(SUMMARY_DATA!B3)=TRUE,"",SUMMARY_DATA!B3) -> 2.4519223 | N50: =IF(ISBLANK(SUMMARY_DATA!C3)=TRUE,"",SUMMARY_DATA!C3) -> 12.799681 | P50: =IF(ISBLANK(SUMMARY_DATA!D3)=TRUE,"",SUMMARY_DATA!D3) -> 3.1550345 | R50: =IF(ISBLANK(SUMMARY_DATA!E3)=TRUE,"",SUMMARY_DATA!E3) -> 5.7525972 | T50: =IF(ISBLANK(SUMMARY_DATA!F3)=TRUE,"",SUMMARY_DATA!F3) -> 1.3572666 | AA50: =IF(ISBLANK(SUMMARY_DATA!G3)=TRUE,"",SUMMARY_DATA!G3) -> 4.5622008 | AC50: =IF(ISBLANK(SUMMARY_DATA!H3)=TRUE,"",SUMMARY_DATA!H3) -> 3.1409309 | AE50: =IF(ISBLANK(SUMMARY_DATA!I3)=TRUE,"",SUMMARY_DATA!I3) -> 1.7618599
A51: =IF(ISBLANK(SUMMARY_DATA!A4)=TRUE,"",SUMMARY_DATA!A4) -> PIMCO: PIMCO Commodity Alpha Fund | J51: =IF(ISBLANK(SUMMARY_DATA!B4)=TRUE,"",SUMMARY_DATA!B4) -> 0.86866099 | N51: =IF(ISBLANK(SUMMARY_DATA!C4)=TRUE,"",SUMMARY_DATA!C4) -> 3.9419554 | P51: =IF(ISBLANK(SUMMARY_DATA!D4)=TRUE,"",SUMMARY_DATA!D4) -> 0.76642305 | R51: =IF(ISBLANK(SUMMARY_DATA!E4)=TRUE,"",SUMMARY_DATA!E4) -> 1.602493 | T51: =IF(ISBLANK(SUMMARY_DATA!F4)=TRUE,"",SUMMARY_DATA!F4) -> 0.44874509 | AA51: =IF(ISBLANK(SUMMARY_DATA!G4)=TRUE,"",SUMMARY_DATA!G4) -> 3.9659145 | AC51: =IF(ISBLANK(SUMMARY_DATA!H4)=TRUE,"",SUMMARY_DATA!H4) -> 2.1536702 | AE51: =IF(ISBLANK(SUMMARY_DATA!I4)=TRUE,"",SUMMARY_DATA!I4) -> 1.3853514
A52: =IF(ISBLANK(SUMMARY_DATA!A5)=TRUE,"",SUMMARY_DATA!A5) -> Graham Absolute Return Ltd: Graham Absolute Return Ltd | J52: =IF(ISBLANK(SUMMARY_DATA!B5)=TRUE,"",SUMMARY_DATA!B5) -> 2.953922 | N52: =IF(ISBLANK(SUMMARY_DATA!C5)=TRUE,"",SUMMARY_DATA!C5) -> 12.454063 | P52: =IF(ISBLANK(SUMMARY_DATA!D5)=TRUE,"",SUMMARY_DATA!D5) -> 4.2246702 | R52: =IF(ISBLANK(SUMMARY_DATA!E5)=TRUE,"",SUMMARY_DATA!E5) -> 6.4583783 | T52: =IF(ISBLANK(SUMMARY_DATA!F5)=TRUE,"",SUMMARY_DATA!F5) -> 2.3210597 | AA52: =IF(ISBLANK(SUMMARY_DATA!G5)=TRUE,"",SUMMARY_DATA!G5) -> 3.684631 | AC52: =IF(ISBLANK(SUMMARY_DATA!H5)=TRUE,"",SUMMARY_DATA!H5) -> 3.4910394 | AE52: =IF(ISBLANK(SUMMARY_DATA!I5)=TRUE,"",SUMMARY_DATA!I5) -> 1.6418692
A53: =IF(ISBLANK(SUMMARY_DATA!A6)=TRUE,"",SUMMARY_DATA!A6) -> Saba: CEF1 MN - 2.75x | J53: =IF(ISBLANK(SUMMARY_DATA!B6)=TRUE,"",SUMMARY_DATA!B6) -> 1.2214834 | N53: =IF(ISBLANK(SUMMARY_DATA!C6)=TRUE,"",SUMMARY_DATA!C6) -> 4.6594918 | P53: =IF(ISBLANK(SUMMARY_DATA!D6)=TRUE,"",SUMMARY_DATA!D6) -> 1.8678244 | R53: =IF(ISBLANK(SUMMARY_DATA!E6)=TRUE,"",SUMMARY_DATA!E6) -> 2.611006 | T53: =IF(ISBLANK(SUMMARY_DATA!F6)=TRUE,"",SUMMARY_DATA!F6) -> 1.79201 | AA53: =IF(ISBLANK(SUMMARY_DATA!G6)=TRUE,"",SUMMARY_DATA!G6) -> 3.3337494 | AC53: =IF(ISBLANK(SUMMARY_DATA!H6)=TRUE,"",SUMMARY_DATA!H6) -> 3.7325828 | AE53: =IF(ISBLANK(SUMMARY_DATA!I6)=TRUE,"",SUMMARY_DATA!I6) -> 1.6052194
...

Sheet SUMMARY_DATA
A1: TOP 5 RISK CONTRIBUTORS - POSITIONS
A2: Silver Point Capital: Silver Point Distressed Opportunity Institutional Partners + Silver Point HF | B2: 0.77463136 | C2: 7.5420822 | D2: 2.0514522 | E2: 3.4079492 | F2: 0.96608254 | G2: 8.5089926 | H2: 6.464386 | I2: 3.3037878
A3: LibreMax Partners LP: LibreMax Partners LP | B3: 2.4519223 | C3: 12.799681 | D3: 3.1550345 | E3: 5.7525972 | F3: 1.3572666 | G3: 4.5622008 | H3: 3.1409309 | I3: 1.7618599
A4: PIMCO: PIMCO Commodity Alpha Fund | B4: 0.86866099 | C4: 3.9419554 | D4: 0.76642305 | E4: 1.602493 | F4: 0.44874509 | G4: 3.9659145 | H4: 2.1536702 | I4: 1.3853514
A5: Graham Absolute Return Ltd: Graham Absolute Return Ltd | B5: 2.953922 | C5: 12.454063 | D5: 4.2246702 | E5: 6.4583783 | F5: 2.3210597 | G5: 3.684631 | H5: 3.4910394 | I5: 1.6418692
A6: Saba: CEF1 MN - 2.75x | B6: 1.2214834 | C6: 4.6594918 | D6: 1.8678244 | E6: 2.611006 | F6: 1.79201 | G6: 3.3337494 | H6: 3.7325828 | I6: 1.6052194
A8: TOP 5 RISK DIVERSIFIERS - POSITIONS
A9: DYAL: DYAL II - Aksia | B9: 1.9130169 | C9: -4.9577199 | D9: 2.6406145 | E9: 0.51031426 | F9: 2.6393619 | G9: -2.2648796 | H9: 3.3693579 | I9: 0.20032401
A10: LibreMax CLO: LibreMax CLO | B10: 2.0217776 | C10: -1.5395183 | D10: 0.028637601 | E10: -0.37425995 | F10: 0.73649479 | G10: -0.66547759 | H10: 0.034575161 | I10: -0.13901257
A11: DE Shaw Composite Fund LLC: DE Shaw Composite Fund LLC | B11: 9.3802815 | C11: -7.0757864 | D11: 9.7672504 | E11: 5.5487738 | F11: 14.257919 | G11: -0.65923583 | H11: 2.5416598 | I11: 0.44421708
A12: Brevan Howard MB Macro Fund: Brevan Howard MB Macro Fund with proforma | B12: 2.6002026 | C12: -1.7935205 | D12: 1.8080417 | E12: 0.91589207 | F12: 2.4690797 | G12: -0.60281092 | H12: 1.6973142 | I12: 0.26451556
A13: Ares: Ares Pathfinder II | B13: 1.6485661 | C13: -0.97570762 | D13: 1.3646659 | E13: 0.69449676 | F13: 1.7267151 | G13: -0.51724379 | H13: 2.0206028 | I13: 0.31635738
A15: UP-RIGHT - SIMULATED PORTFOLIO RISK STATISTICS
A16: 00000MP87KPZC-3AM47H-TTQARV | B16: 0.75095534 | C16: 2.6013856 | D16: 0.9376494 | E16: 11.251793 | F16: 0.87394068 | G16: 0.28728808 | H16: -2.0635408 | I16: 2.4409617
A22: Factor Risk
A23: Factor Risk | B23: 47.149713
A25: Factor Risk
A26: Factor Risk | B26: 115.77315
A29: Portfolio Composition
A30: Multi Strategy | B30: 29.910414
A31: Relative Value | B31: 19.285614
A32: Global Macro | B32: 14.563052
A33: Dockside | B33: 13.589956
A34: Equity Long Short | B34: 8.6928088
A35: Credit | B35: 6.6920936
A36: Specialty Finance | B36: 5.1152413
A37: Coinvests | B37: 2.1508199

Sheet HISTORICAL RISK
A4: DETAILED HISTORICAL STATISTICS
A5: Ex-post (Historical) information about the assets in the portfolio
G7: HISTORICAL STATISTICS
G8: Weight | I8: Mean | K8: StDev | M8: Sharpe | O8: STARR | Q8: Rachev | S8: Skew | U8: Excess Kurtosis | W8: Upside Volatility | Y8: Max Drawdown (%) | AA8: Downside Volatility | AC8: Total Winning Periods | AE8: Total Losing Periods | AG8: Ann.Mean | AI8: Ann. StDev
A9: 12267: Trexquant Onshore Fund LP | G9: 3.1198357 | I9: 1.0714815 | K9: 2.7732815 | M9: 0.26616416 | O9: 0.13287995 | Q9: 1.1476148 | S9: -0.35813677 | U9: 0.52433027 | W9: 1.8450521 | Y9: 8.05852 | AA9: 1.9567993 | AC9: 57 | AE9: 24 | AG9: =IF(ISBLANK(I9)=TRUE,"",I9*12) -> 12.857778 | AI9: =IF(ISBLANK(K9)=TRUE,"",K9*SQRT(12)) -> 9.6069289
A10: Aquatic: Aquatic - Nautilus CFM (Net) | G10: 0.38382851 | I10: -0.59070988 | K10: 3.2964614 | M10: -0.28031368 | O10: -0.11889196 | Q10: 0.70764431 | S10: -0.34573448 | U10: -0.12929051 | W10: 1.5874962 | Y10: 53.023867 | AA10: 2.3075354 | AC10: 39 | AE10: 42 | AG10: =IF(ISBLANK(I10)=TRUE,"",I10*12) -> -7.0885185 | AI10: =IF(ISBLANK(K10)=TRUE,"",K10*SQRT(12)) -> 11.419277
A11: Ares: Ares Pathfinder II | G11: 1.6485661 | I11: 0.99953086 | K11: 2.4718761 | M11: 0.26951089 | O11: 0.26098272 | Q11: 3.7605723 | S11: 2.1223157 | U11: 10.458279 | W11: 2.6226884 | Y11: 7.7806 | AA11: 3.7834455 | AC11: 79 | AE11: 2 | AG11: =IF(ISBLANK(I11)=TRUE,"",I11*12) -> 11.99437 | AI11: =IF(ISBLANK(K11)=TRUE,"",K11*SQRT(12)) -> 8.56283
A12: Bayview Asset Management: MSR Fund | G12: 2.2527339 | I12: 0.76405802 | K12: 0.83007776 | M12: 0.5188968 | O12: 0.30058074 | Q12: 1.113069 | S12: -7.0557875 | U12: 58.545269 | W12: 0.30165825 | Y12: 6.06 | AA12: 4.2284986 | AC12: 79 | AE12: 2 | AG12: =IF(ISBLANK(I12)=TRUE,"",I12*12) -> 9.1686963 | AI12: =IF(ISBLANK(K12)=TRUE,"",K12*SQRT(12)) -> 2.8754737
A13: Benefit Street Partners: Benefit Street Partners Origination Fund (CCFLX) | G13: 0.074708538 | I13: 0.8767284 | K13: 1.2028065 | M13: 0.45177263 | O13: 0.49157117 | Q13: 3.6423548 | S13: 5.4820265 | U13: 45.27914 | W13: 1.1229234 | Y13: 2.15 | AA13: 1.0369588 | AC13: 76 | AE13: 5 | AG13: =IF(ISBLANK(I13)=TRUE,"",I13*12) -> 10.520741 | AI13: =IF(ISBLANK(K13)=TRUE,"",K13*SQRT(12)) -> 4.1666439
A14: BlackRock: GAO | G14: 2.3161392 | I14: 1.2238272 | K14: 2.5901726 | M14: 0.3437971 | O14: 0.27526857 | Q14: 2.4397218 | S14: 0.6274458 | U14: 0.58996153 | W14: 2.0488955 | Y14: 5.3062721 | AA14: 0.97837613 | AC14: 55 | AE14: 26 | AG14: =IF(ISBLANK(I14)=TRUE,"",I14*12) -> 14.685926 | AI14: =IF(ISBLANK(K14)=TRUE,"",K14*SQRT(12)) -> 8.972621
A15: Blackstone: Badgerstone Access | G15: 5.0884559 | I15: 0.90211975 | K15: 0.9046461 | M15: 0.62873915 | O15: 1.0778084 | Q15: 6.2826283 | S15: 1.1036542 | U15: 2.9265605 | W15: 0.80004345 | Y15: 0.82781485 | AA15: 0.23978028 | AC15: 69 | AE15: 12 | AG15: =IF(ISBLANK(I15)=TRUE,"",I15*12) -> 10.825437 | AI15: =IF(ISBLANK(K15)=TRUE,"",K15*SQRT(12)) -> 3.133786
A16: Blue Owl: Blue Owl Funding Partners (CCLFX) | G16: 0.31241515 | I16: 0.84897654 | K16: 1.0539468 | M16: 0.48924976 | O16: 0.84879541 | Q16: 6.7930453 | S16: 1.782033 | U16: 6.2391716 | W16: 0.99566105 | Y16: 2.15 | AA16: 1.1615507 | AC16: 78 | AE16: 3 | AG16: =IF(ISBLANK(I16)=TRUE,"",I16*12) -> 10.187719 | AI16: =IF(ISBLANK(K16)=TRUE,"",K16*SQRT(12)) -> 3.6509787
A17: Brevan Howard Coinvests (Aksia): Brevan Howard Special Opportunities SPC | G17: 0.63216727 | I17: 0.25170741 | K17: 4.1750216 | M17: -0.019551019 | O17: -0.009796855 | Q17: 1.3375091 | S17: -0.19749069 | U17: 6.2696774 | W17: 3.2020631 | Y17: 37.348796 | AA17: 3.0206739 | AC17: 43 | AE17: 38 | AG17: =IF(ISBLANK(I17)=TRUE,"",I17*12) -> 3.0204889 | AI17: =IF(ISBLANK(K17)=TRUE,"",K17*SQRT(12)) -> 14.462699
A18: Brevan Howard MB Macro Fund: Brevan Howard MB Macro Fund with proforma | G18: 2.6002026 | I18: 0.8908284 | K18: 1.6667634 | M18: 0.33447762 | O18: 0.20678408 | Q18: 1.6845727 | S18: -0.024429776 | U18: 0.76532594 | W18: 1.1667057 | Y18: 4.3158265 | AA18: 0.95197621 | AC18: 61 | AE18: 20 | AG18: =IF(ISBLANK(I18)=TRUE,"",I18*12) -> 10.689941 | AI18: =IF(ISBLANK(K18)=TRUE,"",K18*SQRT(12)) -> 5.7738379
A19: D. E. Shaw: Cogence | G19: 1.9781362 | I19: 1.6964556 | K19: 2.7684984 | M19: 0.49236879 | O19: 0.3063196 | Q19: 1.7696629 | S19: 0.020854954 | U19: 1.3372808 | W19: 2.057393 | Y19: 8.2034 | AA19: 1.7979819 | AC19: 63 | AE19: 18 | AG19: =IF(ISBLANK(I19)=TRUE,"",I19*12) -> 20.357467 | AI19: =IF(ISBLANK(K19)=TRUE,"",K19*SQRT(12)) -> 9.5903598
A20: DE Shaw Composite Fund LLC: DE Shaw Composite Fund LLC | G20: 9.3802815 | I20: 1.4251519 | K20: 1.0274129 | M20: 1.0626872 | O20: 4.1928515 | Q20: 14.871736 | S20: 0.67740955 | U20: 1.3904342 | W20: 0.94066441 | Y20: 0.4098 | AA20: 0.13087777 | AC20: 74 | AE20: 7 | AG20: =IF(ISBLANK(I20)=TRUE,"",I20*12) -> 17.101822 | AI20: =IF(ISBLANK(K20)=TRUE,"",K20*SQRT(12)) -> 3.5590626
... A45: Walleye: Walleye Opportunities Fund | G45: 3.5814946 | I45: 0.94420494 | K45: 1.9389349 | M45: 0.31505524 | O45: 0.20156289 | Q45: 2.0127529 | S45: 0.61809322 | U45: 7.774838 | W45: 1.5995428 | Y45: 7 | AA45: 1.5057421 | AC45: 61 | AE45: 20 | AG45: =IF(ISBLANK(I45)=TRUE,"",I45*12) -> 11.330459 | AI45: =IF(ISBLANK(K45)=TRUE,"",K45*SQRT(12)) -> 6.7166675
AG46: =IF(ISBLANK(I46)=TRUE,"",I46*12) | AI46: =IF(ISBLANK(K46)=TRUE,"",K46*SQRT(12))
AG47: =IF(ISBLANK(I47)=TRUE,"",I47*12) | AI47: =IF(ISBLANK(K47)=TRUE,"",K47*SQRT(12))
AG48: =IF(ISBLANK(I48)=TRUE,"",I48*12) | AI48: =IF(ISBLANK(K48)=TRUE,"",K48*SQRT(12))
AG49: =IF(ISBLANK(I49)=TRUE,"",I49*12) | AI49: =IF(ISBLANK(K49)=TRUE,"",K49*SQRT(12))
AG50: =IF(ISBLANK(I50)=TRUE,"",I50*12) | AI50: =IF(ISBLANK(K50)=TRUE,"",K50*SQRT(12))
AG51: =IF(ISBLANK(I51)=TRUE,"",I51*12) | AI51: =IF(ISBLANK(K51)=TRUE,"",K51*SQRT(12))
AG52: =IF(ISBLANK(I52)=TRUE,"",I52*12) | AI52: =IF(ISBLANK(K52)=TRUE,"",K52*SQRT(12))
AG53: =IF(ISBLANK(I53)=TRUE,"",I53*12) | AI53: =IF(ISBLANK(K53)=TRUE,"",K53*SQRT(12))
AG54: =IF(ISBLANK(I54)=TRUE,"",I54*12) | AI54: =IF(ISBLANK(K54)=TRUE,"",K54*SQRT(12))
AG55: =IF(ISBLANK(I55)=TRUE,"",I55*12) | AI55: =IF(ISBLANK(K55)=TRUE,"",K55*SQRT(12))
AG56: =IF(ISBLANK(I56)=TRUE,"",I56*12) | AI56: =IF(ISBLANK(K56)=TRUE,"",K56*SQRT(12))
AG57: =IF(ISBLANK(I57)=TRUE,"",I57*12) | AI57: =IF(ISBLANK(K57)=TRUE,"",K57*SQRT(12))
... AG83: =IF(ISBLANK(I83)=TRUE,"",I83*12) | AI83: =IF(ISBLANK(K83)=TRUE,"",K83*SQRT(12))

Sheet SIMULATED RISK
A4: DETAILED SIMULATED RISK STATISTICS
A5: Ex-ante (Simulated) statistics for portfolio and assets
G7: SIMULATED STATISTICS
G8: Weight | I8: ETR (%) | K8: ETL (%) | M8: VaR(%) | O8: PC to StDev (%) | Q8: PC to ETL (%) • | S8: PC to ETR (%) • | U8: MC to StDev (bps) | W8: MC to ETL (bps) | Y8: MC to ETR | AA8: PC to Return
A9: Current 7.26 | G9: 100 | I9: 2.4409617 | K9: 0.87394068 | M9: 0.28728808 | O9: 100 | Q9: 100 | S9: 100 | AA9: 100
A10: Coinvests | G10: 2.1508199 | I10: 5.1194606 | K10: 3.7155407 | M10: 2.5626743 | O10: 1.7959471 | Q10: 1.8814124 | S10: 1.8035228 | U10: 0.62705206 | W10: 0.76447256 | Y10: 2.0468148 | AA10: 1.2087765
A11: Brevan Howard Coinvests (Aksia): Brevan Howard Special Opportunities SPC | G11: 0.63216727 | I11: 9.301136 | K11: 7.4569555 | M11: 5.5038922 | O11: 0.15244034 | Q11: -0.35162447 | S11: 0.36461956 | U11: 0.18108481 | W11: -0.48610383 | Y11: 1.4078906 | AA11: 0.15861723
A12: HF: Current Coinvests (Excluding BH Coinvests) | G12: 1.5186526 | I12: 6.342087 | K12: 4.7769625 | M12: 3.3566353 | O12: 1.6435067 | Q12: 2.2330368 | S12: 1.4389032 | U12: 0.81269418 | W12: 1.2850481 | Y12: 2.3127788 | AA12: 1.0501593
A13: Credit | G13: 6.6920936 | I13: 4.6156241 | K13: 3.9996909 | M13: 2.4511342 | O13: 10.070044 | Q13: 18.998554 | S13: 6.9948532 | U13: 1.1300131 | W13: 2.4810784 | Y13: 2.5513942 | AA13: 5.0733679
A14: Benefit Street Partners: Benefit Street Partners Origination Fund (CCFLX) | G14: 0.074708538 | I14: 2.6701565 | K14: 0.76548264 | M14: 0.33810438 | O14: 0.014358306 | Q14: -0.041206618 | S14: 0.034903801 | U14: 0.14432684 | W14: -0.48203513 | Y14: 1.1404164 | AA14: 0.06954936
A15: Blue Owl: Blue Owl Funding Partners (CCLFX) | G15: 0.31241515 | I15: 3.7858317 | K15: 0.83186561 | M15: 0.45820667 | O15: 0.11343669 | Q15: -0.077156142 | S15: 0.19093011 | U15: 0.27266888 | W15: -0.21583426 | Y15: 1.4917749 | AA15: 0.28285448
A16: King Street Capital LP: King Street Capital LP | G16: 0.061233379 | I16: 3.2682707 | K16: 4.38086 | M16: 3.0140197 | O16: 0.05328955 | Q16: 0.14474075 | S16: 0.019131274 | U16: 0.65353361 | W16: 2.0657822 | Y16: 0.7626348 | AA16: -0.0045952032
A17: LibreMax CLO: LibreMax CLO | G17: 2.0217776 | I17: 3.8398542 | K17: 3.64007 | M17: 2.3798548 | O17: -0.37425995 | Q17: -1.5395183 | S17: 0.028637601 | U17: -0.13901257 | W17: -0.66547759 | Y17: 0.034575161 | AA17: 0.73649479
A18: LibreMax Partners LP: LibreMax Partners LP | G18: 2.4519223 | I18: 6.3598225 | K18: 7.0560159 | M18: 4.6273557 | O18: 5.7525972 | Q18: 12.799681 | S18: 3.1550345 | U18: 1.7618599 | W18: 4.5622008 | Y18: 3.1409309 | AA18: 1.3572666
A19: Silver Point Capital Fund II LP: Silver Point Capital Fund II LP | G19: 0.99540528 | I19: 8.9126466 | K19: 2.7710748 | M19: 1.8439552 | O19: 1.102673 | Q19: 0.16993092 | S19: 1.5147637 | U19: 0.83188046 | W19: 0.14919505 | Y19: 3.7145474 | AA19: 1.6657154
A20: Silver Point Capital: Silver Point Distressed Opportunity Institutional Partners + Silver Point HF | G20: 0.77463136 | I20: 14.922523 | K20: 13.930755 | M20: 8.90648 | O20: 3.4079492 | Q20: 7.5420822 | S20: 2.0514522 | U20: 3.3037878 | W20: 8.5089926 | Y20: 6.464386 | AA20: 0.96608254
A21: Dockside | G21: 13.589956 | I21: 3.9051153 | K21: 2.1224448 | M21: 1.23642 | O21: 19.710672 | Q21: 25.089923 | S21: 17.643214 | U21: 1.0891745 | W21: 1.6134786 | Y21: 3.168988 | AA21: 14.166789
... A54: HF: Current Specialty Finance (Excluding Pathfinder) | G54: 3.4666752 | I54: 4.0530587 | K54: 2.7827868 | M54: 1.6243823 | O54: 4.5704652 | Q54: 7.0467326 | S54: 3.6899738 | U54: 0.99005965 | W54: 1.7764648 | Y54: 2.5981911 | AA54: 3.2415104

Sheet RISK BUDGETING (ETL)
A4: RISK BUDGETING (ETL)
A5: Implied Return (IR) is the required return of the asset to justify its contribution to the portfolio risk assuming that the current portfolio has optimal performance ratio. To improve the risk-adjusted performance of the portfolio one should consider increasing the weights of the assets with IRs lower that the expected returns of those assets and lowering those with IRs higher than their expected retuns.
Z9: Weight (%) | AB9: Mean | AD9: MC to ETL | AF9: Implied Return (ETL) | AH9: Difference
Q10: Current 7.26 | Z10: 100 | AB10: 0.9376494
P11: =IF(ISBLANK(Q11)=TRUE,"",1) -> 1 | Q11: Coinvests | Z11: 2.1508199 | AB11: 0.5269658 | AD11: 0.76447256 | AF11: 0.82020125 | AH11: -0.29323544
P12: =IF(ISBLANK(Q12)=TRUE,"",2) -> 2 | Q12: Brevan Howard Coinvests (Aksia): Brevan Howard Special Opportunities SPC | Z12: 0.63216727 | AB12: 0.23526582 | AD12: -0.48610383 | AF12: -0.52153993 | AH12: 0.75680575
P13: =IF(ISBLANK(Q13)=TRUE,"",3) -> 3 | Q13: HF: Current Coinvests (Excluding BH Coinvests) | Z13: 1.5186526 | AB13: 0.64839132 | AD13: 1.2850481 | AF13: 1.3787258 | AH13: -0.73033453
P14: =IF(ISBLANK(Q14)=TRUE,"",4) -> 4 | Q14: Credit | Z14: 6.6920936 | AB14: 0.71084487 | AD14: 2.4810784 | AF14: 2.6619446 | AH14: -1.9510997
P15: =IF(ISBLANK(Q15)=TRUE,"",5) -> 5 | Q15: Benefit Street Partners: Benefit Street Partners Origination Fund (CCFLX) | Z15: 0.074708538 | AB15: 0.87289776 | AD15: -0.48203513 | AF15: -0.51717463 | AH15: 1.3900724
P16: =IF(ISBLANK(Q16)=TRUE,"",6) -> 6 | Q16: Blue Owl: Blue Owl Funding Partners (CCLFX) | Z16: 0.31241515 | AB16: 0.84892915 | AD16: -0.21583426 | AF16: -0.23156819 | AH16: 1.0804973
P17: =IF(ISBLANK(Q17)=TRUE,"",7) -> 7 | Q17: King Street Capital LP: King Street Capital LP | Z17: 0.061233379 | AB17: -0.070365046 | AD17: 2.0657822 | AF17: 2.2163741 | AH17: -2.2867391
P18: =IF(ISBLANK(Q18)=TRUE,"",8) -> 8 | Q18: LibreMax CLO: LibreMax CLO | Z18: 2.0217776 | AB18: 0.34156768 | AD18: -0.66547759 | AF18: -0.71398972 | AH18: 1.0555574
P19: =IF(ISBLANK(Q19)=TRUE,"",9) -> 9 | Q19: LibreMax Partners LP: LibreMax Partners LP | Z19: 2.4519223 | AB19: 0.51903774 | AD19: 4.5622008 | AF19: 4.8947771 | AH19: -4.3757394
P20: =IF(ISBLANK(Q20)=TRUE,"",10) -> 10 | Q20: Silver Point Capital Fund II LP: Silver Point Capital Fund II LP | Z20: 0.99540528 | AB20: 1.5690665 | AD20: 0.14919505 | AF20: 0.16007111 | AH20: 1.4089953
P21: =IF(ISBLANK(Q21)=TRUE,"",11) -> 11 | Q21: Silver Point Capital: Silver Point Distressed Opportunity Institutional Partners + Silver Point HF | Z21: 0.77463136 | AB21: 1.1693907 | AD21: 8.5089926 | AF21: 9.1292829 | AH21: -7.9598922
P22: =IF(ISBLANK(Q22)=TRUE,"",12) -> 12 | Q22: Dockside | Z22: 13.589956 | AB22: 0.97744842 | AD22: 1.6134786 | AF22: 1.7310983 | AH22: -0.75364993
P23: =IF(ISBLANK(Q23)=TRUE,"",13) -> 13 | Q23: 12267: Trexquant Onshore Fund LP | Z23: 3.1198357 | AB23: 1.070413 | AD23: 0.079299843 | AF23: 0.08508066 | AH23: 0.98533231
P24: =IF(ISBLANK(Q24)=TRUE,"",14) -> 14 | Q24: Dockside: I-94 Minus Standalones | Z24: 6.254264 | AB24: 1.0463513 | AD24: 2.4134516 | AF24: 2.5893879 | AH24: -1.5430366
P25: =IF(ISBLANK(Q25)=TRUE,"",15) -> 15 | Q25: Dorsal Capital Partners LP: Dorsal Capital Partners LP | Z25: 2.9943734 | AB25: 0.57425515 | AD25: 0.83931385 | AF25: 0.90049833 | AH25: -0.32624318
P26: =IF(ISBLANK(Q26)=TRUE,"",16) -> 16 | Q26: Saba: CEF1 MN - 2.75x | Z26: 1.2214834 | AB26: 1.3756037 | AD26: 3.3337494 | AF26: 3.5767738 | AH26: -2.20117
P27: =IF(ISBLANK(Q27)=TRUE,"",17) -> 17 | Q27: Equity Long Short | Z27: 8.6928088 | AB27: 0.82495862 | AD27: -0.068971375 | AF27: -0.073999265 | AH27: 0.89895788
P28: =IF(ISBLANK(Q28)=TRUE,"",18) -> 18 | Q28: Four World: FWGO | Z28: 2.1319734 | AB28: 0.86964862 | AD28: 0.054908594 | AF28: 0.058911332 | AH28: 0.81073729
P29: =IF(ISBLANK(Q29)=TRUE,"",19) -> 19 | Q29: Four World: FWGO Minority Descent | Z29: 1.7445328 | AB29: 0.6302408 | AD29: 0.87795682 | AF29: 0.9419583 | AH29: -0.3117175
P30: =IF(ISBLANK(Q30)=TRUE,"",20) -> 20 | Q30: Holocene: Holocene Advisors Master | Z30: 4.8163025 | AB30: 0.87570579 | AD30: -0.46679857 | AF30: -0.50082736 | AH30: 1.3765331
P31: =IF(ISBLANK(Q31)=TRUE,"",21) -> 21 | Q31: Global Macro | Z31: 14.563052 | AB31: 0.96297434 | AD31: 2.1472414 | AF31: 2.3037714 | AH31: -1.3407971
P32: =IF(ISBLANK(Q32)=TRUE,"",22) -> 22 | Q32: Brevan Howard MB Macro Fund: Brevan Howard MB Macro Fund with proforma | Z32: 2.6002026 | AB32: 0.89036567 | AD32: -0.60281092 | AF32: -0.64675475 | AH32: 1.5371204
P33: =IF(ISBLANK(Q33)=TRUE,"",23) -> 23 | Q33: Graham Absolute Return Ltd: Graham Absolute Return Ltd | Z33: 2.953922 | AB33: 0.73676293 | AD33: 3.684631 | AF33: 3.953234 | AH33: -3.2164711
P34: =IF(ISBLANK(Q34)=TRUE,"",24) -> 24 | Q34: Mesarete: Prior TR+back with Pharo Macro+Mesarete Capital Fund | Z34: 2.6503264 | AB34: 0.5603043 | AD34: 2.6105921 | AF34: 2.8008996 | AH34: -2.2405953
P35: =IF(ISBLANK(Q35)=TRUE,"",25) -> 25 | Q35: PIMCO: PIMCO Commodity Alpha Fund | Z35: 0.86866099 | AB35: 0.48438409 | AD35: 3.9659145 | AF35: 4.2550225 | AH35: -3.7706385
P36: =IF(ISBLANK(Q36)=TRUE,"",26) -> 26 | Q36: Rokos Global Macro Fund LP: Rokos Global Macro Fund LP | Z36: 5.4899402 | AB36: 1.389199 | AD36: 2.1110885 | AF36: 2.2649831 | AH36: -0.87578407
P37: =IF(ISBLANK(Q37)=TRUE,"",27) -> 27 | Q37: Multi Strategy | Z37: 29.910414 | AB37: 1.0985524 | AD37: 0.13950148 | AF37: 0.14967089 | AH37: 0.94888151
P38: =IF(ISBLANK(Q38)=TRUE,"",28) -> 28 | Q38: Blackstone: Badgerstone Access | Z38: 5.0884559 | AB38: 0.90210472 | AD38: -0.18409756 | AF38: -0.19751794 | AH38: 1.0996227
P39: =IF(ISBLANK(Q39)=TRUE,"",29) -> 29 | Q39: D. E. Shaw: Cogence | Z39: 1.9781362 | AB39: 1.7007494 | AD39: 2.2178291 | AF39: 2.3795049 | AH39: -0.67875552
P40: =IF(ISBLANK(Q40)=TRUE,"",30) -> 30 | Q40: DE Shaw Composite Fund LLC: DE Shaw Composite Fund LLC | Z40: 9.3802815 | AB40: 1.4252162 | AD40: -0.65923583 | AF40: -0.70729294 | AH40: 2.1325092
P41: =IF(ISBLANK(Q41)=TRUE,"",31) -> 31 | Q41: DYAL: DYAL II - Aksia | Z41: 1.9130169 | AB41: 1.2936614 | AD41: -2.2648796 | AF41: -2.4299853 | AH41: 3.7236467
P42: =IF(ISBLANK(Q42)=TRUE,"",32) -> 32 | Q42: Elliott Associates LP: Elliott Associates LP | Z42: 7.9690284 | AB42: 0.71204297 | AD42: 0.16092826 | AF42: 0.17265964 | AH42: 0.53938333
P43: =IF(ISBLANK(Q43)=TRUE,"",33) -> 33 | Q43: Walleye: Walleye Opportunities Fund | Z43: 3.5814946 | AB43: 0.94527756 | AD43: 2.7799233 | AF43: 2.9825747 | AH43: -2.0372972
P44: =IF(ISBLANK(Q44)=TRUE,"",34) -> 34 | Q44: Relative Value | Z44: 19.285614 | AB44: 0.82337777 | AD44: 0.36659533 | AF44: 0.39331948 | AH44: 0.43005829
P45: =IF(ISBLANK(Q45)=TRUE,"",35) -> 35 | Q45: Aquatic: Aquatic - Nautilus CFM (Net) | Z45: 0.38382851 | AB45: -0.59150315 | AD45: 1.9869707 | AF45: 2.1318173 | AH45: -2.7233205
F46: • Implied Return (ETL) | I46: • Mean Return (%) | P46: =IF(ISBLANK(Q46)=TRUE,"",36) -> 36 | Q46: Bayview Asset Management: MSR Fund | Z46: 2.2527339 | AB46: 0.76373881 | AD46: 0.50817708 | AF46: 0.54522228 | AH46: 0.21851653
...

Sheet RB_ETL
B1: Portfolio/Groups | C1: Mean | D1: MC to ETL | E1: Impl.Return | F1: Diff | I1: Assets | J1: Mean | K1: MC to ETL | L1: Impl.Return | M1: Diff
B2: Current 7.26 | C2: 0.9376494 | I2: Current 7.26 | J2: 0.9376494
A3: {=INDEX('RISK BUDGETING (ETL)'!P$11:P$87, MATCH(1, (B3='RISK BUDGETING (ETL)'!Q$11:Q$87) * (C3='RISK BUDGETING (ETL)'!AB$11:AB$87) * (D3='RISK BUDGETING (ETL)'!AD$11:AD$87) * (E3='RISK BUDGETING (ETL)'!AF$11:AF$87), 0))} -> 1 | B3: Coinvests | C3: 0.5269658 | D3: 0.76447256 | E3: 0.82020125 | F3: -0.29323544 | H3: {=INDEX('RISK BUDGETING (ETL)'!P$11:P$87, MATCH(1, (I3='RISK BUDGETING (ETL)'!Q$11:Q$87) * (J3='RISK BUDGETING (ETL)'!AB$11:AB$87) * (K3='RISK BUDGETING (ETL)'!AD$11:AD$87) * (L3='RISK BUDGETING (ETL)'!AF$11:AF$87), 0))} -> 13 | I3: 12267: Trexquant Onshore Fund LP | J3: 1.070413 | K3: 0.079299843 | L3: 0.08508066 | M3: 0.98533231
A4: {=INDEX('RISK BUDGETING (ETL)'!P$11:P$87, MATCH(1, (B4='RISK BUDGETING (ETL)'!Q$11:Q$87) * (C4='RISK BUDGETING (ETL)'!AB$11:AB$87) * (D4='RISK BUDGETING (ETL)'!AD$11:AD$87) * (E4='RISK BUDGETING (ETL)'!AF$11:AF$87), 0))} -> 4 | B4: Credit | C4: 0.71084487 | D4: 2.4810784 | E4: 2.6619446 | F4: -1.9510997 | H4: {=INDEX('RISK BUDGETING (ETL)'!P$11:P$87, MATCH(1, (I4='RISK BUDGETING (ETL)'!Q$11:Q$87) * (J4='RISK BUDGETING (ETL)'!AB$11:AB$87) * (K4='RISK BUDGETING (ETL)'!AD$11:AD$87) * (L4='RISK BUDGETING (ETL)'!AF$11:AF$87), 0))} -> 35 | I4: Aquatic: Aquatic - Nautilus CFM (Net) | J4: -0.59150315 | K4: 1.9869707 | L4: 2.1318173 | M4: -2.7233205
A5: {=INDEX('RISK BUDGETING (ETL)'!P$11:P$87, MATCH(1, (B5='RISK BUDGETING (ETL)'!Q$11:Q$87) * (C5='RISK BUDGETING (ETL)'!AB$11:AB$87) * (D5='RISK BUDGETING (ETL)'!AD$11:AD$87) * (E5='RISK BUDGETING (ETL)'!AF$11:AF$87), 0))} -> 12 | B5: Dockside | C5: 0.97744842 | D5: 1.6134786 | E5: 1.7310983 | F5: -0.75364993 | H5: {=INDEX('RISK BUDGETING (ETL)'!P$11:P$87, MATCH(1, (I5='RISK BUDGETING (ETL)'!Q$11:Q$87) * (J5='RISK BUDGETING (ETL)'!AB$11:AB$87) * (K5='RISK BUDGETING (ETL)'!AD$11:AD$87) * (L5='RISK BUDGETING (ETL)'!AF$11:AF$87), 0))} -> 44 | I5: Ares: Ares Pathfinder II | J5: 0.98209792 | K5: -0.51724379 | L5: -0.55494994 | M5: 1.5370479
A6: {=INDEX('RISK BUDGETING (ETL)'!P$11:P$87, MATCH(1, (B6='RISK BUDGETING (ETL)'!Q$11:Q$87) * (C6='RISK BUDGETING (ETL)'!AB$11:AB$87) * (D6='RISK BUDGETING (ETL)'!AD$11:AD$87) * (E6='RISK BUDGETING (ETL)'!AF$11:AF$87), 0))} -> 17 | B6: Equity Long Short | C6: 0.82495862 | D6: -0.068971375 | E6: -0.073999265 | F6: 0.89895788 | H6: {=INDEX('RISK BUDGETING (ETL)'!P$11:P$87, MATCH(1, (I6='RISK BUDGETING (ETL)'!Q$11:Q$87) * (J6='RISK BUDGETING (ETL)'!AB$11:AB$87) * (K6='RISK BUDGETING (ETL)'!AD$11:AD$87) * (L6='RISK BUDGETING (ETL)'!AF$11:AF$87), 0))} -> 36 | I6: Bayview Asset Management: MSR Fund | J6: 0.76373881 | K6: 0.50817708 | L6: 0.54522228 | M6: 0.21851653
A7: {=INDEX('RISK BUDGETING (ETL)'!P$11:P$87, MATCH(1, (B7='RISK BUDGETING (ETL)'!Q$11:Q$87) * (C7='RISK BUDGETING (ETL)'!AB$11:AB$87) * (D7='RISK BUDGETING (ETL)'!AD$11:AD$87) * (E7='RISK BUDGETING (ETL)'!AF$11:AF$87), 0))} -> 21 | B7: Global Macro | C7: 0.96297434 | D7: 2.1472414 | E7: 2.3037714 | F7: -1.3407971 | H7: {=INDEX('RISK BUDGETING (ETL)'!P$11:P$87, MATCH(1, (I7='RISK BUDGETING (ETL)'!Q$11:Q$87) * (J7='RISK BUDGETING (ETL)'!AB$11:AB$87) * (K7='RISK BUDGETING (ETL)'!AD$11:AD$87) * (L7='RISK BUDGETING (ETL)'!AF$11:AF$87), 0))} -> 5 | I7: Benefit Street Partners: Benefit Street Partners Origination Fund (CCFLX) | J7: 0.87289776 | K7: -0.48203513 | L7: -0.51717463 | M7: 1.3900724
A8: {=INDEX('RISK BUDGETING (ETL)'!P$11:P$87, MATCH(1, (B8='RISK BUDGETING (ETL)'!Q$11:Q$87) * (C8='RISK BUDGETING (ETL)'!AB$11:AB$87) * (D8='RISK BUDGETING (ETL)'!AD$11:AD$87) * (E8='RISK BUDGETING (ETL)'!AF$11:AF$87), 0))} -> 27 | B8: Multi Strategy | C8: 1.0985524 | D8: 0.13950148 | E8: 0.14967089 | F8: 0.94888151 | H8: {=INDEX('RISK BUDGETING (ETL)'!P$11:P$87, MATCH(1, (I8='RISK BUDGETING (ETL)'!Q$11:Q$87) * (J8='RISK BUDGETING (ETL)'!AB$11:AB$87) * (K8='RISK BUDGETING (ETL)'!AD$11:AD$87) * (L8='RISK BUDGETING (ETL)'!AF$11:AF$87), 0))} -> 37 | I8: BlackRock: GAO | J8: 1.2240246 | K8: 0.29927867 | L8: 0.32109555 | M8: 0.90292904
A9: {=INDEX('RISK BUDGETING (ETL)'!P$11:P$87, MATCH(1, (B9='RISK BUDGETING (ETL)'!Q$11:Q$87) * (C9='RISK BUDGETING (ETL)'!AB$11:AB$87) * (D9='RISK BUDGETING (ETL)'!AD$11:AD$87) * (E9='RISK BUDGETING (ETL)'!AF$11:AF$87), 0))} -> 34 | B9: Relative Value | C9: 0.82337777 | D9: 0.36659533 | E9: 0.39331948 | F9: 0.43005829 | H9: {=INDEX('RISK BUDGETING (ETL)'!P$11:P$87, MATCH(1, (I9='RISK BUDGETING (ETL)'!Q$11:Q$87) * (J9='RISK BUDGETING (ETL)'!AB$11:AB$87) * (K9='RISK BUDGETING (ETL)'!AD$11:AD$87) * (L9='RISK BUDGETING (ETL)'!AF$11:AF$87), 0))} -> 28 | I9: Blackstone: Badgerstone Access | J9: 0.90210472 | K9: -0.18409756 | L9: -0.19751794 | M9: 1.0996227
A10: {=INDEX('RISK BUDGETING (ETL)'!P$11:P$87, MATCH(1, (B10='RISK BUDGETING (ETL)'!Q$11:Q$87) * (C10='RISK BUDGETING (ETL)'!AB$11:AB$87) * (D10='RISK BUDGETING (ETL)'!AD$11:AD$87) * (E10='RISK BUDGETING (ETL)'!AF$11:AF$87), 0))} -> 43 | B10: Specialty Finance | C10: 0.91070065 | D10: 1.0372366 | E10: 1.1128493 | F10: -0.20214869 | H10: {=INDEX('RISK BUDGETING (ETL)'!P$11:P$87, MATCH(1, (I10='RISK BUDGETING (ETL)'!Q$11:Q$87) * (J10='RISK BUDGETING (ETL)'!AB$11:AB$87) * (K10='RISK BUDGETING (ETL)'!AD$11:AD$87) * (L10='RISK BUDGETING (ETL)'!AF$11:AF$87), 0))} -> 6 | I10: Blue Owl: Blue Owl Funding Partners (CCLFX) | J10: 0.84892915 | K10: -0.21583426 | L10: -0.23156819 | M10: 1.0804973
A11: {=INDEX('RISK BUDGETING (ETL)'!P$11:P$87, MATCH(1, (B11='RISK BUDGETING (ETL)'!Q$11:Q$87) * (C11='RISK BUDGETING (ETL)'!AB$11:AB$87) * (D11='RISK BUDGETING (ETL)'!AD$11:AD$87) * (E11='RISK BUDGETING (ETL)'!AF$11:AF$87), 0))} | H11: {=INDEX('RISK BUDGETING (ETL)'!P$11:P$87, MATCH(1, (I11='RISK BUDGETING (ETL)'!Q$11:Q$87) * (J11='RISK BUDGETING (ETL)'!AB$11:AB$87) * (K11='RISK BUDGETING (ETL)'!AD$11:AD$87) * (L11='RISK BUDGETING (ETL)'!AF$11:AF$87), 0))} -> 2 | I11: Brevan Howard Coinvests (Aksia): Brevan Howard Special Opportunities SPC | J11: 0.23526582 | K11: -0.48610383 | L11: -0.52153993 | M11: 0.75680575
A12: {=INDEX('RISK BUDGETING (ETL)'!P$11:P$87, MATCH(1, (B12='RISK BUDGETING (ETL)'!Q$11:Q$87) * (C12='RISK BUDGETING (ETL)'!AB$11:AB$87) * (D12='RISK BUDGETING (ETL)'!AD$11:AD$87) * (E12='RISK BUDGETING (ETL)'!AF$11:AF$87), 0))} | H12: {=INDEX('RISK BUDGETING (ETL)'!P$11:P$87, MATCH(1, (I12='RISK BUDGETING (ETL)'!Q$11:Q$87) * (J12='RISK BUDGETING (ETL)'!AB$11:AB$87) * (K12='RISK BUDGETING (ETL)'!AD$11:AD$87) * (L12='RISK BUDGETING (ETL)'!AF$11:AF$87), 0))} -> 22 | I12: Brevan Howard MB Macro Fund: Brevan Howard MB Macro Fund with proforma | J12: 0.89036567 | K12: -0.60281092 | L12: -0.64675475 | M12: 1.5371204
A13: {=INDEX('RISK BUDGETING (ETL)'!P$11:P$87, MATCH(1, (B13='RISK BUDGETING (ETL)'!Q$11:Q$87) * (C13='RISK BUDGETING (ETL)'!AB$11:AB$87) * (D13='RISK BUDGETING (ETL)'!AD$11:AD$87) * (E13='RISK BUDGETING (ETL)'!AF$11:AF$87), 0))} | H13: {=INDEX('RISK BUDGETING (ETL)'!P$11:P$87, MATCH(1, (I13='RISK BUDGETING (ETL)'!Q$11:Q$87) * (J13='RISK BUDGETING (ETL)'!AB$11:AB$87) * (K13='RISK BUDGETING (ETL)'!AD$11:AD$87) * (L13='RISK BUDGETING (ETL)'!AF$11:AF$87), 0))} -> 29 | I13: D. E. Shaw: Cogence | J13: 1.7007494 | K13: 2.2178291 | L13: 2.3795049 | M13: -0.67875552
A14: {=INDEX('RISK BUDGETING (ETL)'!P$11:P$87, MATCH(1, (B14='RISK BUDGETING (ETL)'!Q$11:Q$87) * (C14='RISK BUDGETING (ETL)'!AB$11:AB$87) * (D14='RISK BUDGETING (ETL)'!AD$11:AD$87) * (E14='RISK BUDGETING (ETL)'!AF$11:AF$87), 0))} | H14: {=INDEX('RISK BUDGETING (ETL)'!P$11:P$87, MATCH(1, (I14='RISK BUDGETING (ETL)'!Q$11:Q$87) * (J14='RISK BUDGETING (ETL)'!AB$11:AB$87) * (K14='RISK BUDGETING (ETL)'!AD$11:AD$87) * (L14='RISK BUDGETING (ETL)'!AF$11:AF$87), 0))} -> 30 | I14: DE Shaw Composite Fund LLC: DE Shaw Composite Fund LLC | J14: 1.4252162 | K14: -0.65923583 | L14: -0.70729294 | M14: 2.1325092
A15: {=INDEX('RISK BUDGETING (ETL)'!P$11:P$87, MATCH(1, (B15='RISK BUDGETING (ETL)'!Q$11:Q$87) * (C15='RISK BUDGETING (ETL)'!AB$11:AB$87) * (D15='RISK BUDGETING (ETL)'!AD$11:AD$87) * (E15='RISK BUDGETING (ETL)'!AF$11:AF$87), 0))} | H15: {=INDEX('RISK BUDGETING (ETL)'!P$11:P$87, MATCH(1, (I15='RISK BUDGETING (ETL)'!Q$11:Q$87) * (J15='RISK BUDGETING (ETL)'!AB$11:AB$87) * (K15='RISK BUDGETING (ETL)'!AD$11:AD$87) * (L15='RISK BUDGETING (ETL)'!AF$11:AF$87), 0))} -> 31 | I15: DYAL: DYAL II - Aksia | J15: 1.2936614 | K15: -2.2648796 | L15: -2.4299853 | M15: 3.7236467
A16: {=INDEX('RISK BUDGETING (ETL)'!P$11:P$87, MATCH(1, (B16='RISK BUDGETING (ETL)'!Q$11:Q$87) * (C16='RISK BUDGETING (ETL)'!AB$11:AB$87) * (D16='RISK BUDGETING (ETL)'!AD$11:AD$87) * (E16='RISK BUDGETING (ETL)'!AF$11:AF$87), 0))} | H16: {=INDEX('RISK BUDGETING (ETL)'!P$11:P$87, MATCH(1, (I16='RISK BUDGETING (ETL)'!Q$11:Q$87) * (J16='RISK BUDGETING (ETL)'!AB$11:AB$87) * (K16='RISK BUDGETING (ETL)'!AD$11:AD$87) * (L16='RISK BUDGETING (ETL)'!AF$11:AF$87), 0))} -> 14 | I16: Dockside: I-94 Minus Standalones | J16: 1.0463513 | K16: 2.4134516 | L16: 2.5893879 | M16: -1.5430366
A17: {=INDEX('RISK BUDGETING (ETL)'!P$11:P$87, MATCH(1, (B17='RISK BUDGETING (ETL)'!Q$11:Q$87) * (C17='RISK BUDGETING (ETL)'!AB$11:AB$87) * (D17='RISK BUDGETING (ETL)'!AD$11:AD$87) * (E17='RISK BUDGETING (ETL)'!AF$11:AF$87), 0))} | H17: {=INDEX('RISK BUDGETING (ETL)'!P$11:P$87, MATCH(1, (I17='RISK BUDGETING (ETL)'!Q$11:Q$87) * (J17='RISK BUDGETING (ETL)'!AB$11:AB$87) * (K17='RISK BUDGETING (ETL)'!AD$11:AD$87) * (L17='RISK BUDGETING (ETL)'!AF$11:AF$87), 0))} -> 15 | I17: Dorsal Capital Partners LP: Dorsal Capital Partners LP | J17: 0.57425515 | K17: 0.83931385 | L17: 0.90049833 | M17: -0.32624318
A18: {=INDEX('RISK BUDGETING (ETL)'!P$11:P$87, MATCH(1, (B18='RISK BUDGETING (ETL)'!Q$11:Q$87) * (C18='RISK BUDGETING (ETL)'!AB$11:AB$87) * (D18='RISK BUDGETING (ETL)'!AD$11:AD$87) * (E18='RISK BUDGETING (ETL)'!AF$11:AF$87), 0))} | H18: {=INDEX('RISK BUDGETING (ETL)'!P$11:P$87, MATCH(1, (I18='RISK BUDGETING (ETL)'!Q$11:Q$87) * (J18='RISK BUDGETING (ETL)'!AB$11:AB$87) * (K18='RISK BUDGETING (ETL)'!AD$11:AD$87) * (L18='RISK BUDGETING (ETL)'!AF$11:AF$87), 0))} -> 32 | I18: Elliott Associates LP: Elliott Associates LP | J18: 0.71204297 | K18: 0.16092826 | L18: 0.17265964 | M18: 0.53938333
A19: {=INDEX('RISK BUDGETING (ETL)'!P$11:P$87, MATCH(1, (B19='RISK BUDGETING (ETL)'!Q$11:Q$87) * (C19='RISK BUDGETING (ETL)'!AB$11:AB$87) * (D19='RISK BUDGETING (ETL)'!AD$11:AD$87) * (E19='RISK BUDGETING (ETL)'!AF$11:AF$87), 0))} | H19: {=INDEX('RISK BUDGETING (ETL)'!P$11:P$87, MATCH(1, (I19='RISK BUDGETING (ETL)'!Q$11:Q$87) * (J19='RISK BUDGETING (ETL)'!AB$11:AB$87) * (K19='RISK BUDGETING (ETL)'!AD$11:AD$87) * (L19='RISK BUDGETING (ETL)'!AF$11:AF$87), 0))} -> 18 | I19: Four World: FWGO | J19: 0.86964862 | K19: 0.054908594 | L19: 0.058911332 | M19: 0.81073729
A20: {=INDEX('RISK BUDGETING (ETL)'!P$11:P$87, MATCH(1, (B20='RISK BUDGETING (ETL)'!Q$11:Q$87) * (C20='RISK BUDGETING (ETL)'!AB$11:AB$87) * (D20='RISK BUDGETING (ETL)'!AD$11:AD$87) * (E20='RISK BUDGETING (ETL)'!AF$11:AF$87), 0))} | H20: {=INDEX('RISK BUDGETING (ETL)'!P$11:P$87, MATCH(1, (I20='RISK BUDGETING (ETL)'!Q$11:Q$87) * (J20='RISK BUDGETING (ETL)'!AB$11:AB$87) * (K20='RISK BUDGETING (ETL)'!AD$11:AD$87) * (L20='RISK BUDGETING (ETL)'!AF$11:AF$87), 0))} -> 19 | I20: Four World: FWGO Minority Descent | J20: 0.6302408 | K20: 0.87795682 | L20: 0.9419583 | M20: -0.3117175
A21: {=INDEX('RISK BUDGETING (ETL)'!P$11:P$87, MATCH(1, (B21='RISK BUDGETING (ETL)'!Q$11:Q$87) * (C21='RISK BUDGETING (ETL)'!AB$11:AB$87) * (D21='RISK BUDGETING (ETL)'!AD$11:AD$87) * (E21='RISK BUDGETING (ETL)'!AF$11:AF$87), 0))} | H21: {=INDEX('RISK BUDGETING (ETL)'!P$11:P$87, MATCH(1, (I21='RISK BUDGETING (ETL)'!Q$11:Q$87) * (J21='RISK BUDGETING (ETL)'!AB$11:AB$87) * (K21='RISK BUDGETING (ETL)'!AD$11:AD$87) * (L21='RISK BUDGETING (ETL)'!AF$11:AF$87), 0))} -> 23 | I21: Graham Absolute Return Ltd: Graham Absolute Return Ltd | J21: 0.73676293 | K21: 3.684631 | L21: 3.953234 | M21: -3.2164711
A22: {=INDEX('RISK BUDGETING (ETL)'!P$11:P$87, MATCH(1, (B22='RISK BUDGETING (ETL)'!Q$11:Q$87) * (C22='RISK BUDGETING (ETL)'!AB$11:AB$87) * (D22='RISK BUDGETING (ETL)'!AD$11:AD$87) * (E22='RISK BUDGETING (ETL)'!AF$11:AF$87), 0))} | H22: {=INDEX('RISK BUDGETING (ETL)'!P$11:P$87, MATCH(1, (I22='RISK BUDGETING (ETL)'!Q$11:Q$87) * (J22='RISK BUDGETING (ETL)'!AB$11:AB$87) * (K22='RISK BUDGETING (ETL)'!AD$11:AD$87) * (L22='RISK BUDGETING (ETL)'!AF$11:AF$87), 0))} -> 3 | I22: HF: Current Coinvests (Excluding BH Coinvests) | J22: 0.64839132 | K22: 1.2850481 | L22: 1.3787258 | M22: -0.73033453
